Workbook

Sheet Sheet1
L6: Hanum Sukma Zahrani
L7: E-mail: hanum.zahrani@mail.utoronto.ca
L8: University of Toronto (STG)
L10: Student ID: 1010180340
L12: Project 1 to construct a portfolio of 90-day US T-Bills AND SRA Consisting of 2 Equities
L14: Next Month Equity RoR and Risk estimated by:
M15: 1. Stats Analog
M17: 2. Shrinkage
M19: 3. Wiener Stochastic Process for RoR ~ N(GM, s^2)
M21: 4. Ito Stochastic Process for RoR ~ N(GM - (s^2)/2, s^2)

Sheet FRED 90-Day T-Bill Data
A1: DGS3MO
A2: lin | B2: Percent, Not Seasonally Adjusted
A3: m, avg | B3: Monthly
A4: 29830 | B4: 1981-09-01 to 2024-10-01
A5: Market Yield on U.S. Treasury Securities at 3-Month Constant Maturity, Quoted on an Investment Basis
A6: Board of Governors of the Federal Reserve System (US)
A7: 3-Month Treasury Constant Maturity Rate
A10: FRED Data | B10: FRED Data | D10: Simple method | E10: (1 + r_1mo)^6 = (1 + r_6mo)
A11: date | B11: Annualized Yield (%) | C11: r_a (decimal) | D11: r_6mo = r_a/2 | E11: r_1mo = (1 + r_6mo)^(1/6) - 1
A12: 29830 | B12: 15.61 | C12: =B12/100 -> 0.1561 | D12: =C12/2 -> 0.07805 | E12: =(1+D12)^(1/6) - 1 -> 0.012604417
A13: 29860 | B13: 14.23 | C13: =B13/100 -> 0.1423 | D13: =C13/2 -> 0.07115 | E13: =(1+D13)^(1/6) - 1 -> 0.011521338
A14: 29891 | B14: 11.35 | C14: =B14/100 -> 0.1135 | D14: =C14/2 -> 0.05675 | E14: =(1+D14)^(1/6) - 1 -> 0.0092421407
A15: 29921 | B15: 11.32 | C15: =B15/100 -> 0.1132 | D15: =C15/2 -> 0.0566 | E15: =(1+D15)^(1/6) - 1 -> 0.0092182632
A16: 29952 | B16: 12.92 | C16: =B16/100 -> 0.1292 | D16: =C16/2 -> 0.0646 | E16: =(1+D16)^(1/6) - 1 -> 0.010487806
A17: 29983 | B17: 14.28 | C17: =B17/100 -> 0.1428 | D17: =C17/2 -> 0.0714 | E17: =(1+D17)^(1/6) - 1 -> 0.011560681
A18: 30011 | B18: 13.31 | C18: =B18/100 -> 0.1331 | D18: =C18/2 -> 0.06655 | E18: =(1+D18)^(1/6) - 1 -> 0.010796051
A19: 30042 | B19: 13.34 | C19: =B19/100 -> 0.1334 | D19: =C19/2 -> 0.0667 | E19: =(1+D19)^(1/6) - 1 -> 0.010819743
A20: 30072 | B20: 12.71 | C20: =B20/100 -> 0.1271 | D20: =C20/2 -> 0.06355 | E20: =(1+D20)^(1/6) - 1 -> 0.010321633
A21: 30103 | B21: 13.08 | C21: =B21/100 -> 0.1308 | D21: =C21/2 -> 0.0654 | E21: =(1+D21)^(1/6) - 1 -> 0.010614322
A22: 30133 | B22: 11.86 | C22: =B22/100 -> 0.1186 | D22: =C22/2 -> 0.0593 | E22: =(1+D22)^(1/6) - 1 -> 0.0096476266
A23: 30164 | B23: 9 | C23: =B23/100 -> 0.09 | D23: =C23/2 -> 0.045 | E23: =(1+D23)^(1/6) - 1 -> 0.007363123
... A529: 45566 | B529: 4.7181818 | C529: =B529/100 -> 0.047181818 | D529: =C529/2 -> 0.023590909 | E529: =(1+D529)^(1/6) - 1 -> 0.0038937182

Sheet CRSP-DATA
A1: CRSP Data for ED + SP500 | G1: CRSP Data for ESS + SP500 | M1: Scrubbed Data ESS & ED & SP500
A2: Look for N/A, -88, -66, -99 (i.e. big #s) and delete those rows | G2: Look for N/A, -88, -66, -99 (i.e. big #s) and delete those rows | M2: Common Date Range
A3: LAST DATE: 12/31/23 | G3: LAST DATE: 12/31/23 | M3: LAST DATE: 12/31/23
A4: Date | B4: Company # | C4: Company | D4: Company-RET | E4: SP500-RET | G4: Date | H4: Company # | I4: Company | J4: Company-RET | K4: SP500-RET | M4: Date | N4: ESS-RET | O4: ED-RET | P4: SP500-RET
A5: 9497 | B5: 11404 | C5: CONSOLIDATED EDISON INC | D5: -66 | G5: 34485 | H5: 80681 | I5: ESSEX PROPERTY TRUST INC | J5: -88 | K5: 0.012419 | M5: 34544 | N5: 0.007092 | O5: 0.084906 | P5: 0.031467
A6: 9527 | B6: 11404 | C6: CONSOLIDATED EDISON INC | D6: 0.039683 | E6: 0.022472 | G6: 34515 | H6: 80681 | I6: ESSEX PROPERTY TRUST INC | J6: -66 | K6: -0.026812 | M6: 34577 | N6: 0.035211 | O6: -0.034783 | P6: 0.037643
A7: 9555 | B7: 11404 | C7: CONSOLIDATED EDISON INC | D7: -0.001272 | E7: -0.043956 | G7: 34544 | H7: 80681 | I7: ESSEX PROPERTY TRUST INC | J7: 0.007092 | K7: 0.031467 | M7: 34607 | N7: 0.002313 | O7: -0.087156 | P7: -0.026898
A8: 9587 | B8: 11404 | C8: CONSOLIDATED EDISON INC | D8: -0.060645 | E8: -0.059113 | G8: 34577 | H8: 80681 | I8: ESSEX PROPERTY TRUST INC | J8: 0.035211 | K8: 0.037643 | M8: 34638 | N8: -0.020833 | O8: 0 | P8: 0.020834
A9: 9617 | B9: 11404 | C9: CONSOLIDATED EDISON INC | D9: 0.021978 | E9: 0.022688 | G9: 34607 | H9: 80681 | I9: ESSEX PROPERTY TRUST INC | J9: 0.002313 | K9: -0.026898 | M9: 34668 | N9: -0.035461 | O9: 0.060302 | P9: -0.039505
A10: 9645 | B10: 11404 | C10: CONSOLIDATED EDISON INC | D10: 0.040323 | E10: 0.007679 | G10: 34638 | H10: 80681 | I10: ESSEX PROPERTY TRUST INC | J10: -0.020833 | K10: 0.020834 | M10: 34698 | N10: -0.085735 | O10: -0.004831 | P10: 0.012299
A11: 9678 | B11: 11404 | C11: CONSOLIDATED EDISON INC | D11: 0.036649 | E11: 0.043184 | G11: 34668 | H11: 80681 | I11: ESSEX PROPERTY TRUST INC | J11: -0.035461 | K11: -0.039505 | M11: 34730 | N11: 0.090909 | O11: 0.097087 | P11: 0.024278
A12: 9709 | B12: 11404 | C12: CONSOLIDATED EDISON INC | D12: 0.107323 | E12: 0.045455 | G12: 34698 | H12: 80681 | I12: ESSEX PROPERTY TRUST INC | J12: -0.085735 | K12: 0.012299 | M12: 34758 | N12: -0.022727 | O12: -0.004071 | P12: 0.036074
A13: 9740 | B13: 11404 | C13: CONSOLIDATED EDISON INC | D13: 0.005701 | E13: 0.017081 | G13: 34730 | H13: 80681 | I13: ESSEX PROPERTY TRUST INC | J13: 0.090909 | K13: 0.024278 | M13: 34789 | N13: 0.010388 | O13: -0.013575 | P13: 0.027329
A14: 9770 | B14: 11404 | C14: CONSOLIDATED EDISON INC | D14: 0.009174 | E14: 0.022901 | G14: 34758 | H14: 80681 | I14: ESSEX PROPERTY TRUST INC | J14: -0.022727 | K14: 0.036074 | M14: 34817 | N14: 0.023622 | O14: 0.018349 | P14: 0.02796
A15: 9800 | B15: 11404 | C15: CONSOLIDATED EDISON INC | D15: -0.032955 | E15: -0.031343 | G15: 34789 | H15: 80681 | I15: ESSEX PROPERTY TRUST INC | J15: 0.010388 | K15: 0.027329 | M15: 34850 | N15: 0.1 | O15: 0.094955 | P15: 0.036312
A16: 9831 | B16: 11404 | C16: CONSOLIDATED EDISON INC | D16: 0.059929 | E16: 0.022342 | G16: 34817 | H16: 80681 | I16: ESSEX PROPERTY TRUST INC | J16: 0.023622 | K16: 0.02796 | M16: 34880 | N16: 0.037343 | O16: -0.012552 | P16: 0.021279
A17: 9862 | B17: 11404 | C17: CONSOLIDATED EDISON INC | D17: -0.024664 | E17: 0.016579 | G17: 34850 | H17: 80681 | I17: ESSEX PROPERTY TRUST INC | J17: 0.1 | K17: 0.036312 | M17: 34911 | N17: -0.02069 | O17: -0.016949 | P17: 0.031776
... A358: 20240 | B358: 11404 | C358: CONSOLIDATED EDISON INC | D358: 0.004511 | E358: -0.001317 | G358: 45230 | H358: 80681 | I358: ESSEX PROPERTY TRUST INC | J358: 0.008628 | K358: -0.02198 | M358: 45289 | N358: 0.172351 | O358: 0.009544 | P358: 0.044229
A359: 20270 | B359: 11404 | C359: CONSOLIDATED EDISON INC | D359: -0.010101 | E359: 0.0823 | G359: 45260 | H359: 80681 | I359: ESSEX PROPERTY TRUST INC | J359: -0.00215 | K359: 0.089179
A360: 20299 | B360: 11404 | C360: CONSOLIDATED EDISON INC | D360: 0.043367 | E360: 0.060687 | G360: 45289 | H360: 80681 | I360: ESSEX PROPERTY TRUST INC | J360: 0.172351 | K360: 0.044229
A361: 20332 | B361: 11404 | C361: CONSOLIDATED EDISON INC | D361: 0.023961 | E361: -0.007813
A362: 20362 | B362: 11404 | C362: CONSOLIDATED EDISON INC | D362: -0.045894 | E362: 0.011348
A363: 20393 | B363: 11404 | C363: CONSOLIDATED EDISON INC | D363: -0.017722 | E363: -0.030456
A364: 20423 | B364: 11404 | C364: CONSOLIDATED EDISON INC | D364: 0.002062 | E364: 0.07487
A365: 20453 | B365: 11404 | C365: CONSOLIDATED EDISON INC | D365: -0.013021 | E365: -0.000659
A366: 20485 | B366: 11404 | C366: CONSOLIDATED EDISON INC | D366: 0.01847 | E366: -0.0365
A367: 20514 | B367: 11404 | C367: CONSOLIDATED EDISON INC | D367: 0.004663 | E367: 0.034687
A368: 20543 | B368: 11404 | C368: CONSOLIDATED EDISON INC | D368: 0.007833 | E368: 0.069255
A369: 20575 | B369: 11404 | C369: CONSOLIDATED EDISON INC | D369: -0.028497 | E369: -0.002063
A370: 20606 | B370: 11404 | C370: CONSOLIDATED EDISON INC | D370: -0.0032 | E370: -0.06573
A371: 20635 | B371: 11404 | C371: CONSOLIDATED EDISON INC | D371: -0.00271 | E371: 0.039159
A372: 20667 | B372: 11404 | C372: CONSOLIDATED EDISON INC | D372: 0.057065 | E372: 0.051522
... A1181: 45289 | B1181: 11404 | C1181: CONSOLIDATED EDISON INC | D1181: 0.009544 | E1181: 0.044229

Sheet Google Finance -ESS 
A1: STOCK INFO | D1: Highlight 1st and last trading day of the month | G1: Highlight last trading day of the month
A2: ticker | B2: NYSE:ESS | D2: RESULT | G2: FIRST & LAST DAYS | J2: MONTHLY RETURNS (NO DIV)
A3: attribute | B3: close | D3: Date | E3: Close | G3: Date | H3: Close | J3: Date | K3: Close
A4: start_date | B4: 45292 | D4: 45293 | E4: 249.87 | G4: 45293 | H4: 249.87 | J4: =G5 -> 45322 | K4: =(H5/H4)-1 -> -0.066434546
A5: num_days or end_date | B5: 45657 | D5: 45294 | E5: 242.74 | G5: 45322 | H5: 233.27 | J5: =G7 -> 45351 | K5: =(H7/H6)-1 -> -0.026094276
A6: interval | B6: 1 | D6: 45295 | E6: 243.8 | G6: 45323 | H6: 237.6 | J6: =G9 -> 45379 | K6: =(H9/H8)-1 -> 0.04454495
D7: 45296 | E7: 243.58 | G7: 45351 | H7: 231.4 | J7: =G11 -> 45412 | K7: =(H11/H10)-1 -> 0.027454416
D8: 45299 | E8: 248.33 | G8: 45352 | H8: 234.37 | J8: =G13 -> 45443 | K8: =(H13/H12)-1 -> 0.058337068
D9: 45300 | E9: 247.88 | G9: 45379 | H9: 244.81 | J9: =G15 -> 45471 | K9: =(H15/H14)-1 -> 0.044392434
D10: 45301 | E10: 247.88 | G10: 45383 | H10: 239.67 | J10: =G17 -> 45504 | K10: =(H17/H16)-1 -> 0.020306429
D11: 45302 | E11: 248.08 | G11: 45412 | H11: 246.25 | J11: =G19 -> 45534 | K11: =(H19/H18)-1 -> 0.05635479
D12: 45303 | E12: 249.08 | G12: 45413 | H12: 245.47 | J12: =G21 -> 45565 | K12: =(H21/H20)-1 -> -0.024017972
D13: 45307 | E13: 248.77 | G13: 45443 | H13: 259.79 | J13: =G23 -> 45596 | K13: =(H24/H23)-1 -> -1
D14: 45308 | E14: 241.69 | G14: 45446 | H14: 260.63
D15: 45309 | E15: 238.85 | G15: 45471 | H15: 272.2
D16: 45310 | E16: 240.85 | G16: 45474 | H16: 272.82
D17: 45313 | E17: 242.22 | G17: 45504 | H17: 278.36
D18: 45314 | E18: 238.76 | G18: 45505 | H18: 285.69
D19: 45315 | E19: 234.66 | G19: 45534 | H19: 301.79
D20: 45316 | E20: 233.92 | G20: 45538 | H20: 302.69
D21: 45317 | E21: 236.41 | G21: 45565 | H21: 295.42
D22: 45320 | E22: 236.9 | G22: 45566 | H22: 292.71
D23: 45321 | E23: 234.47 | G23: 45596 | H23: 283.86
D24: 45322 | E24: 233.27
D25: 45323 | E25: 237.6
D26: 45324 | E26: 236.02
D27: 45327 | E27: 230.34
D28: 45328 | E28: 232.97
D29: 45329 | E29: 229.02
D30: 45330 | E30: 229.34
D31: 45331 | E31: 229.8
D32: 45334 | E32: 230.78
D33: 45335 | E33: 225.59
D34: 45336 | E34: 227.26
D35: 45337 | E35: 234.62
... D215: 45597 | E215: 276.97

Sheet Google Finance-ED
A1: STOCK INFO | D1: Highlight 1st and last trading day of the month | G1: Highlight last trading day of the month | J1: MONTHLY RETURNS (NO DIV)
A2: ticker | B2: NYSE:ED | D2: RESULT | G2: FIRST & LAST DAYS | J2: Date | K2: Close
A3: attribute | B3: close | D3: Date | E3: Close | G3: 45293 | H3: 92.41 | J3: =G4 -> 45322 | K3: =(H4/H3)-1 -> -0.016340223
A4: start_date | B4: 45292 | D4: 45293 | E4: 92.41 | G4: 45322 | H4: 90.9 | J4: =G6 -> 45351 | K4: =(H6/H5)-1 -> -0.06003449
A5: num_days or end_date | B5: 45657 | D5: 45294 | E5: 93 | G5: 45323 | H5: 92.78 | J5: =G8 -> 45379 | K5: =(H8/H7)-1 -> 0.043673141
A6: interval | B6: 1 | D6: 45295 | E6: 93.25 | G6: 45351 | H6: 87.21 | J6: =G10 -> 45412 | K6: =(H10/H9)-1 -> 0.045057013
D7: 45296 | E7: 93.52 | G7: 45352 | H7: 87.01 | J7: =G12 -> 45443 | K7: =(H12/H11)-1 -> -0.0026371308
D8: 45299 | E8: 93.81 | G8: 45379 | H8: 90.81 | J8: =G14 -> 45471 | K8: =(H14/H13)-1 -> -0.045473954
D9: 45300 | E9: 93.7 | G9: 45383 | H9: 90.33 | J9: =G16 -> 45504 | K9: =(H16/H15)-1 -> 0.098074541
D10: 45301 | E10: 94.32 | G10: 45412 | H10: 94.4 | J10: =G18 -> 45534 | K10: =(H18/H17)-1 -> 0.013471709
D11: 45302 | E11: 91.25 | G11: 45413 | H11: 94.8 | J11: =G20 -> 45565 | K11: =(H20/H19)-1 -> 0.0082300542
D12: 45303 | E12: 91.62 | G12: 45443 | H12: 94.55 | J12: =G22 -> 45596 | K12: =(H22/H21)-1 -> -0.033000476
D13: 45307 | E13: 91.56 | G13: 45446 | H13: 93.68
D14: 45308 | E14: 90.55 | G14: 45471 | H14: 89.42
D15: 45309 | E15: 89.4 | G15: 45474 | H15: 88.81
D16: 45310 | E16: 89.86 | G16: 45504 | H16: 97.52
D17: 45313 | E17: 89.2 | G17: 45505 | H17: 100.21
D18: 45314 | E18: 89.12 | G18: 45534 | H18: 101.56
D19: 45315 | E19: 88.32 | G19: 45538 | H19: 103.28
D20: 45316 | E20: 89.67 | G20: 45565 | H20: 104.13
D21: 45317 | E21: 90.02 | G21: 45566 | H21: 105.15
D22: 45320 | E22: 90.59 | G22: 45596 | H22: 101.68
D23: 45321 | E23: 90.68
D24: 45322 | E24: 90.9
D25: 45323 | E25: 92.78
D26: 45324 | E26: 91.1
D27: 45327 | E27: 89.67
D28: 45328 | E28: 89.77
D29: 45329 | E29: 89.47
D30: 45330 | E30: 88.67
D31: 45331 | E31: 89.06
D32: 45334 | E32: 89.45
D33: 45335 | E33: 86.67
D34: 45336 | E34: 86.84
... D215: 45597 | E215: 100

Sheet Raw Google
A1: STOCK INFO | D1: STOCK INFO | G1: STOCK INFO
A2: ticker | B2: INDEXSP:.INX | D2: ticker | E2: NYSE:ESS | G2: ticker | H2: NYSE:ED
A3: attribute | B3: close | D3: attribute | E3: close | G3: attribute | H3: close
A4: start_date | B4: 45292 | D4: start_date | E4: 45292 | G4: start_date | H4: 45292
A5: num_days or end_date | B5: 45657 | D5: num_days or end_date | E5: 45657 | G5: num_days or end_date | H5: 45657
A6: interval | B6: 1 | D6: interval | E6: 1 | G6: interval | H6: 1
A8: Date | B8: Close | D8: Date | E8: Close | G8: Date | H8: Close
A9: 45293 | B9: 4742.83 | D9: 45293 | E9: 249.87 | G9: 45293 | H9: 92.41
A10: 45294 | B10: 4704.81 | D10: 45294 | E10: 242.74 | G10: 45294 | H10: 93
A11: 45295 | B11: 4688.68 | D11: 45295 | E11: 243.8 | G11: 45295 | H11: 93.25
A12: 45296 | B12: 4697.24 | D12: 45296 | E12: 243.58 | G12: 45296 | H12: 93.52
A13: 45299 | B13: 4763.54 | D13: 45299 | E13: 248.33 | G13: 45299 | H13: 93.81
A14: 45300 | B14: 4756.5 | D14: 45300 | E14: 247.88 | G14: 45300 | H14: 93.7
A15: 45301 | B15: 4783.45 | D15: 45301 | E15: 247.88 | G15: 45301 | H15: 94.32
A16: 45302 | B16: 4780.24 | D16: 45302 | E16: 248.08 | G16: 45302 | H16: 91.25
A17: 45303 | B17: 4783.83 | D17: 45303 | E17: 249.08 | G17: 45303 | H17: 91.62
A18: 45307 | B18: 4765.98 | D18: 45307 | E18: 248.77 | G18: 45307 | H18: 91.56
A19: 45308 | B19: 4739.21 | D19: 45308 | E19: 241.69 | G19: 45308 | H19: 90.55
A20: 45309 | B20: 4780.94 | D20: 45309 | E20: 238.85 | G20: 45309 | H20: 89.4
... A219: 45597 | B219: 5728.8 | D219: 45596 | E219: 283.86 | G219: 45596 | H219: 101.68
D220: 45597 | E220: 276.97 | G220: 45597 | H220: 100

Sheet FILTERED-DATA
A1: ticker | B1: INDEXSP:.INX | C1: NYSE:ESS | D1: NYSE:ED | F1: SP500_ROR | G1: ESS_ROR | H1: ED_ROR
A2: 45293 | B2: 4742.83 | C2: 249.87 | D2: 92.41
A3: 45322 | B3: 4845.65 | C3: 233.27 | D3: 90.9 | F3: =(B3/B2)-1 -> 0.02167904 | G3: =(C3/C2)-1 -> -0.066434546 | H3: =(D3/D2)-1 -> -0.016340223
A4: 45323 | B4: 4906.19 | C4: 237.6 | D4: 92.78
A5: 45351 | B5: 5096.27 | C5: 231.4 | D5: 87.21 | F5: =(B5/B4)-1 -> 0.038742894 | G5: =(C5/C4)-1 -> -0.026094276 | H5: =(D5/D4)-1 -> -0.06003449 | J5: Date | K5: SP500_ROR | L5: ESS_ROR | M5: ED_ROR
A6: 45352 | B6: 5137.08 | C6: 234.37 | D6: 87.01 | J6: 45322 | K6: 0.021679 | L6: -0.066435 | M6: -0.01634
A7: 45379 | B7: 5254.35 | C7: 244.81 | D7: 90.81 | F7: =(B7/B6)-1 -> 0.022828144 | G7: =(C7/C6)-1 -> 0.04454495 | H7: =(D7/D6)-1 -> 0.043673141 | J7: 45351 | K7: 0.038743 | L7: -0.026094 | M7: -0.060034
A8: 45383 | B8: 5243.77 | C8: 239.67 | D8: 90.33 | J8: 45379 | K8: 0.044545 | L8: 0.044545 | M8: 0.043673
A9: 45412 | B9: 5035.69 | C9: 246.25 | D9: 94.4 | F9: =(B9/B8)-1 -> -0.039681374 | G9: =(C9/C8)-1 -> 0.027454416 | H9: =(D9/D8)-1 -> 0.045057013 | J9: 45412 | K9: 0.027454 | L9: 0.027454 | M9: 0.045057
A10: 45413 | B10: 5018.39 | C10: 245.47 | D10: 94.8 | J10: 45443 | K10: 0.058337 | L10: 0.058337 | M10: -0.002637
A11: 45443 | B11: 5277.51 | C11: 259.79 | D11: 94.55 | F11: =(B11/B10)-1 -> 0.05163409 | G11: =(C11/C10)-1 -> 0.058337068 | H11: =(D11/D10)-1 -> -0.0026371308 | J11: 45471 | K11: 0.044392 | L11: 0.044392 | M11: -0.045474
A12: 45446 | B12: 5283.4 | C12: 260.63 | D12: 93.68 | J12: 45504 | K12: 0.020306 | L12: 0.020306 | M12: 0.098075
A13: 45471 | B13: 5460.48 | C13: 272.2 | D13: 89.42 | F13: =(B13/B12)-1 -> 0.033516296 | G13: =(C13/C12)-1 -> 0.044392434 | H13: =(D13/D12)-1 -> -0.045473954 | J13: 45534 | K13: 0.056355 | L13: 0.056355 | M13: 0.013472
A14: 45474 | B14: 5475.09 | C14: 272.82 | D14: 88.81 | J14: 45565 | K14: -0.024018 | L14: -0.024018 | M14: 0.00823
A15: 45504 | B15: 5522.3 | C15: 278.36 | D15: 97.52 | F15: =(B15/B14)-1 -> 0.0086226893 | G15: =(C15/C14)-1 -> 0.020306429 | H15: =(D15/D14)-1 -> 0.098074541 | J15: 45596 | K15: -0.030235 | L15: -0.030235 | M15: -0.033
A16: 45505 | B16: 5446.68 | C16: 285.69 | D16: 100.21
A17: 45534 | B17: 5648.4 | C17: 301.79 | D17: 101.56 | F17: =(B17/B16)-1 -> 0.037035405 | G17: =(C17/C16)-1 -> 0.05635479 | H17: =(D17/D16)-1 -> 0.013471709
A18: 45538 | B18: 5528.93 | C18: 302.69 | D18: 103.28
A19: 45565 | B19: 5762.48 | C19: 295.42 | D19: 104.13 | F19: =(B19/B18)-1 -> 0.042241446 | G19: =(C19/C18)-1 -> -0.024017972 | H19: =(D19/D18)-1 -> 0.0082300542
A20: 45566 | B20: 5708.75 | C20: 292.71 | D20: 105.15
A21: 45596 | B21: 5705.45 | C21: 283.86 | D21: 101.68 | F21: =(B21/B20)-1 -> -0.00057806 | G21: =(C21/C20)-1 -> -0.030234703 | H21: =(D21/D20)-1 -> -0.033000476

Sheet MASTER-DATA
B1: ESS, ED, SP500, US 90-DAY T-BILL DATA COMMON DATES | K1: SET = LAST DATE
B2: From 1994-07-29 to 2024-10-1 | H2: First date of portofolio: | K2: 45566
A3: Source | B3: yyyy-mm-dd | C3: ESS-RET | D3: ED-RET | E3: SP500-RET | F3: 90-DAY US T-BILLS | H3: r_free last day of prior month | K3: =F366 -> 0.0038937182
A4: CRSP + FRED | B4: 34544 | C4: 0.007092 | D4: 0.084906 | E4: 0.031467 | F4: ='FRED 90-Day T-Bill Data'!$E167 -> 0.003805282
A5: CRSP + FRED | B5: 34577 | C5: 0.035211 | D5: -0.034783 | E5: 0.037643 | F5: ='FRED 90-Day T-Bill Data'!$E168 -> 0.0039197215
A6: CRSP + FRED | B6: 34607 | C6: 0.002313 | D6: -0.087156 | E6: -0.026898 | F6: ='FRED 90-Day T-Bill Data'!$E169 -> 0.004205535
A7: CRSP + FRED | B7: 34638 | C7: -0.020833 | D7: 0 | E7: 0.020834 | F7: ='FRED 90-Day T-Bill Data'!$E170 -> 0.0044909423
A8: CRSP + FRED | B8: 34668 | C8: -0.035461 | D8: 0.060302 | E8: -0.039505 | F8: ='FRED 90-Day T-Bill Data'!$E171 -> 0.0047433935
A9: CRSP + FRED | B9: 34698 | C9: -0.085735 | D9: -0.004831 | E9: 0.012299 | F9: ='FRED 90-Day T-Bill Data'!$E172 -> 0.0048572999
A10: CRSP + FRED | B10: 34730 | C10: 0.090909 | D10: 0.097087 | E10: 0.024278 | F10: ='FRED 90-Day T-Bill Data'!$E173 -> 0.0048898327
A11: CRSP + FRED | B11: 34758 | C11: -0.022727 | D11: -0.004071 | E11: 0.036074 | F11: ='FRED 90-Day T-Bill Data'!$E174 -> 0.0048654336
A12: CRSP + FRED | B12: 34789 | C12: 0.010388 | D12: -0.013575 | E12: 0.027329 | F12: ='FRED 90-Day T-Bill Data'!$E175 -> 0.0048084908
A13: CRSP + FRED | B13: 34817 | C13: 0.023622 | D13: 0.018349 | E13: 0.02796 | F13: ='FRED 90-Day T-Bill Data'!$E176 -> 0.0048166264
A14: CRSP + FRED | B14: 34850 | C14: 0.1 | D14: 0.094955 | E14: 0.036312 | F14: ='FRED 90-Day T-Bill Data'!$E177 -> 0.0046457081
A15: CRSP + FRED | B15: 34880 | C15: 0.037343 | D15: -0.012552 | E15: 0.021279 | F15: ='FRED 90-Day T-Bill Data'!$E178 -> 0.0046049918
... A202: CRSP + FRED | B202: 40574 | C202: 0.015584 | D202: 0.006859 | E202: 0.022646 | F202: ='FRED 90-Day T-Bill Data'!$E365 -> 0.000108304
A203: CRSP + FRED | B203: 40602 | C203: 0.067069 | D203: 0.013424 | E203: 0.031957 | F203: ='FRED 90-Day T-Bill Data'!E366 -> 8.3315978e-05
A204: CRSP + FRED | B204: 40633 | C204: 0.010179 | D204: 0.014806 | E204: -0.001047 | F204: ='FRED 90-Day T-Bill Data'!E367 -> 4.9993751e-05
A205: CRSP + FRED | B205: 40662 | C205: 0.092581 | D205: 0.027602 | E205: 0.028495 | F205: ='FRED 90-Day T-Bill Data'!E368 -> 3.3330556e-05
A206: CRSP + FRED | B206: 40694 | C206: 0.015722 | D206: 0.029547 | E206: -0.013501 | F206: ='FRED 90-Day T-Bill Data'!E369 -> 3.3330556e-05
A207: CRSP + FRED | B207: 40724 | C207: -0.009302 | D207: 0.003392 | E207: -0.018258 | F207: ='FRED 90-Day T-Bill Data'!E370 -> 3.3330556e-05
A208: CRSP + FRED | B208: 40753 | C208: 0.037475 | D208: -0.012021 | E208: -0.021474 | F208: ='FRED 90-Day T-Bill Data'!E371 -> 1.6665972e-05
A209: CRSP + FRED | B209: 40786 | C209: 0.022727 | D209: 0.080038 | E209: -0.056791 | F209: ='FRED 90-Day T-Bill Data'!E372 -> 8.3331597e-06
A210: CRSP + FRED | B210: 40816 | C210: -0.156531 | D210: 0.01441 | E210: -0.071762 | F210: ='FRED 90-Day T-Bill Data'!E373 -> 1.6665972e-05
A211: CRSP + FRED | B211: 40847 | C211: 0.18927 | D211: 0.014907 | E211: 0.107723 | F211: ='FRED 90-Day T-Bill Data'!E374 -> 8.3331597e-06
A212: CRSP + FRED | B212: 40877 | C212: -0.069417 | D212: 0.037152 | E212: -0.005059 | F212: ='FRED 90-Day T-Bill Data'!E375 -> 8.3331597e-06
A213: CRSP + FRED | B213: 40907 | C213: 0.065487 | D213: 0.043925 | E213: 0.008533 | F213: ='FRED 90-Day T-Bill Data'!E376 -> 2.4998438e-05
A214: CRSP + FRED | B214: 40939 | C214: 0.024838 | D214: -0.049492 | E214: 0.043583 | F214: ='FRED 90-Day T-Bill Data'!E377 -> 7.4985941e-05
... A366: FRED + Google-Fin | B366: 45565 | C366: -0.024018 | D366: 0.00823 | E366: -0.024018 | F366: ='FRED 90-Day T-Bill Data'!E529 -> 0.0038937182
B701: 45322 | E701: 0.025493858
B702: 45351 | E702: 0.043182523
B703: 45379 | E703: 0.031646302
B704: 45412 | E704: -0.011232804
B705: 45443 | E705: 0.024005915
B706: 45471 | E706: 0.034367228
B707: 45504 | E707: 0.022688241
B708: 45534 | E708: -0.010796316
B709: 45565 | E709: 0.026112544
B710: 45596 | E710: 0.024028421

Sheet Summary-Stats
B3: Summary Stats: July 1994 - September 2024 | H3: 90-DAY US T-BILL FOR PORTFOLIO
C4: =C18 -> ESS-RET | D4: =D18 -> ED-RET | E4: =E18 -> SP500-RET | F4: =F18 -> 90-DAY US T-BILLS | H4: Date | I4: r_free (mo)
B5: Observations | C5: =COUNT(C30:C392) -> 363 | D5: =COUNT(D30:D392) -> 363 | E5: =COUNT(E30:E392) -> 363 | F5: =COUNT(F30:F392) -> 363 | H5: ='MASTER-DATA'!K2 -> 45566 | I5: ='MASTER-DATA'!K3 -> 0.0038937182 | O5: RISK | P5: AM
B6: Min | C6: =MIN(C30:C392) -> -0.215424 | D6: =MIN(D30:D392) -> -0.153351 | E6: =MIN(E30:E392) -> -0.169425 | F6: =MIN(F30:F392) -> 8.3331597e-06 | N6: ESS | O6: =C12 -> 0.061360906 | P6: =C7 -> 0.013091421
B7: Arithmetic Mean | C7: =AVERAGE(C30:C392) -> 0.013091421 | D7: =AVERAGE(D30:D392) -> 0.0088689366 | E7: =AVERAGE(E30:E392) -> 0.0083072176 | F7: =AVERAGE(F30:F392) -> 0.0020034441 | N7: ED | O7: =D12 -> 0.050081438 | P7: =D7 -> 0.0088689366
B8: Geometric Mean | C8: =((G26)^(1/C5))-1 -> 0.011216185 | D8: =((H26)^(1/D5))-1 -> 0.0076266734 | E8: =((I26)^(1/E5))-1 -> 0.0073394951 | F8: =((J26)^(1/F5))-1 -> 0.0020018062 | H8: Oct 1 Portofolio | I8: =C4 -> ESS-RET | J8: =D4 -> ED-RET | K8: =E4 -> SP500-RET | N8: SP500 | O8: =E12 -> 0.043772104 | P8: =E7 -> 0.0083072176
B9: Max | C9: =MAX(C30:C392) -> 0.208134 | D9: =MAX(D30:D392) -> 0.208155 | E9: =MAX(E30:E392) -> 0.126844 | F9: =MAX(F30:F392) -> 0.0052311097 | H9: RISK PREMIUM | I9: =C7-$I$5 -> 0.0091977033 | J9: =D7-$I$5 -> 0.0049752184 | K9: =F7/$I$5 -> 0.51453238 | N9: T-BILLS | O9: 0 | P9: =I5 -> 0.0038937182
B10: AM - GM | C10: =C7-C8 -> 0.0018752364 | D10: =D7-D8 -> 0.0012422632 | E10: =E7-E8 -> 0.00096772256 | F10: =F7-F8 -> 1.637901e-06 | H10: SHARPE RATIO | I10: =I9/C12 -> 0.14989517 | J10: =J9/D12 -> 0.099342563 | K10: =K9/E12 -> 11.754801
B11: Sample Variance | C11: =_xlfn.VAR.S(C30:C392) -> 0.0037651608 | D11: =_xlfn.VAR.S(D30:D392) -> 0.0025081504 | E11: =_xlfn.VAR.S(E30:E392) -> 0.0019159971 | F11: =_xlfn.VAR.S(F30:F392) -> 3.292641e-06
B12: Sample Std. Dev. | C12: =SQRT(C11) -> 0.061360906 | D12: =SQRT(D11) -> 0.050081438 | E12: =SQRT(E11) -> 0.043772104 | F12: =SQRT(F11) -> 0.0018145636
B13: GM - Var/2 | C13: =C8-C11/2 -> 0.0093336048 | D13: =D8-D11/2 -> 0.0063725982 | E13: =E8-E11/2 -> 0.0063814965 | F13: =F8-F11/2 -> 0.0020001599
B14: RISK PREMIUM: r_AM - rf | C14: =C7-$I$5 -> 0.0091977033 | D14: =D7-$I$5 -> 0.0049752184 | E14: =E7-$I$5 -> 0.0044134994
B15: SHARPE RATIO: Risk Premiumm/Risk | C15: =C14/C12 -> 0.14989517 | D15: =D14/D12 -> 0.099342563 | E15: =E14/E12 -> 0.10082904
B17: Sample Covariances
B18: Var-Cov | C18: =C29 -> ESS-RET | D18: =D29 -> ED-RET | E18: =E29 -> SP500-RET | F18: =F29 -> 90-DAY US T-BILLS
B19: =C18 -> ESS-RET | C19: =_xlfn.COVARIANCE.S($C$30:$C$392,C30:C392) -> 0.0037651608 | D19: =_xlfn.COVARIANCE.S($C$30:$C$392,D30:D392) -> 0.00076141857 | E19: =_xlfn.COVARIANCE.S($C$30:$C$392,E30:E392) -> 0.0011899926 | F19: =_xlfn.COVARIANCE.S($C$30:$C$392,F30:F392) -> 4.8324714e-06
B20: =D18 -> ED-RET | C20: =D19 -> 0.00076141857 | D20: =_xlfn.COVARIANCE.S($D$30:$D$392,D30:D392) -> 0.0025081504 | E20: =_xlfn.COVARIANCE.S($D$30:$D$392,E30:E392) -> 0.00034862787 | F20: =_xlfn.COVARIANCE.S($D$30:$D$392,F30:F392) -> 3.8085614e-07
B21: =E18 -> SP500-RET | C21: =E19 -> 0.0011899926 | D21: =E20 -> 0.00034862787 | E21: =_xlfn.COVARIANCE.S($E$30:$E$392,E30:E392) -> 0.0019159971 | F21: =_xlfn.COVARIANCE.S($E$30:$E$392,F30:F392) -> 4.3957199e-06
B22: =F18 -> 90-DAY US T-BILLS | C22: =F19 -> 4.8324714e-06 | D22: =F20 -> 3.8085614e-07 | E22: =F21 -> 4.3957199e-06 | F22: =_xlfn.COVARIANCE.S($F$30:$F$392,F30:F392) -> 3.292641e-06
G24: Products of (1 + r)
G25: =G29 -> 1 + ESS-RET | H25: =H29 -> 1 + ED-RET | I25: =I29 -> 1 + SP500-RET | J25: =J29 -> 1 + 90-DAY US T-BILLS
G26: =PRODUCT(G30:G392) -> 57.32927 | H26: =PRODUCT(H30:H392) -> 15.767938 | I26: =PRODUCT(I30:I392) -> 14.217978 | J26: =PRODUCT(J30:J392) -> 2.0666508
A29: # | B29: DATE | C29: ESS-RET | D29: ED-RET | E29: SP500-RET | F29: 90-DAY US T-BILLS | G29: 1 + ESS-RET | H29: 1 + ED-RET | I29: 1 + SP500-RET | J29: 1 + 90-DAY US T-BILLS
A30: 1 | B30: 34544 | C30: 0.007092 | D30: 0.084906 | E30: 0.031467 | F30: 0.003805282 | G30: =1+C30 -> 1.007092 | H30: =1+D30 -> 1.084906 | I30: =1+E30 -> 1.031467 | J30: =1+F30 -> 1.0038053
A31: 2 | B31: 34577 | C31: 0.035211 | D31: -0.034783 | E31: 0.037643 | F31: 0.0039197215 | G31: =1+C31 -> 1.035211 | H31: =1+D31 -> 0.965217 | I31: =1+E31 -> 1.037643 | J31: =1+F31 -> 1.0039197
A32: 3 | B32: 34607 | C32: 0.002313 | D32: -0.087156 | E32: -0.026898 | F32: 0.004205535 | G32: =1+C32 -> 1.002313 | H32: =1+D32 -> 0.912844 | I32: =1+E32 -> 0.973102 | J32: =1+F32 -> 1.0042055
A33: 4 | B33: 34638 | C33: -0.020833 | D33: 0 | E33: 0.020834 | F33: 0.0044909423 | G33: =1+C33 -> 0.979167 | H33: =1+D33 -> 1 | I33: =1+E33 -> 1.020834 | J33: =1+F33 -> 1.0044909
A34: 5 | B34: 34668 | C34: -0.035461 | D34: 0.060302 | E34: -0.039505 | F34: 0.0047433935 | G34: =1+C34 -> 0.964539 | H34: =1+D34 -> 1.060302 | I34: =1+E34 -> 0.960495 | J34: =1+F34 -> 1.0047434
A35: 6 | B35: 34698 | C35: -0.085735 | D35: -0.004831 | E35: 0.012299 | F35: 0.0048572999 | G35: =1+C35 -> 0.914265 | H35: =1+D35 -> 0.995169 | I35: =1+E35 -> 1.012299 | J35: =1+F35 -> 1.0048573
A36: 7 | B36: 34730 | C36: 0.090909 | D36: 0.097087 | E36: 0.024278 | F36: 0.0048898327 | G36: =1+C36 -> 1.090909 | H36: =1+D36 -> 1.097087 | I36: =1+E36 -> 1.024278 | J36: =1+F36 -> 1.0048898
A37: 8 | B37: 34758 | C37: -0.022727 | D37: -0.004071 | E37: 0.036074 | F37: 0.0048654336 | G37: =1+C37 -> 0.977273 | H37: =1+D37 -> 0.995929 | I37: =1+E37 -> 1.036074 | J37: =1+F37 -> 1.0048654
A38: 9 | B38: 34789 | C38: 0.010388 | D38: -0.013575 | E38: 0.027329 | F38: 0.0048084908 | G38: =1+C38 -> 1.010388 | H38: =1+D38 -> 0.986425 | I38: =1+E38 -> 1.027329 | J38: =1+F38 -> 1.0048085
A39: 10 | B39: 34817 | C39: 0.023622 | D39: 0.018349 | E39: 0.02796 | F39: 0.0048166264 | G39: =1+C39 -> 1.023622 | H39: =1+D39 -> 1.018349 | I39: =1+E39 -> 1.02796 | J39: =1+F39 -> 1.0048166
A40: 11 | B40: 34850 | C40: 0.1 | D40: 0.094955 | E40: 0.036312 | F40: 0.0046457081 | G40: =1+C40 -> 1.1 | H40: =1+D40 -> 1.094955 | I40: =1+E40 -> 1.036312 | J40: =1+F40 -> 1.0046457
A41: 12 | B41: 34880 | C41: 0.037343 | D41: -0.012552 | E41: 0.021279 | F41: 0.0046049918 | G41: =1+C41 -> 1.037343 | H41: =1+D41 -> 0.987448 | I41: =1+E41 -> 1.021279 | J41: =1+F41 -> 1.004605
... A392: 363 | B392: 45565 | C392: -0.024018 | D392: 0.00823 | E392: -0.024018 | F392: 0.0038937182 | G392: =1+C392 -> 0.975982 | H392: =1+D392 -> 1.00823 | I392: =1+E392 -> 0.975982 | J392: =1+F392 -> 1.0038937

Sheet STATS-PORTFOLIO
A3: OCTOBER MONTHLY RETURNS ON 90-DAY US T-BILLS
A4: Date | B4: r_free (mo)
A5: ='Summary-Stats'!H5 -> 45566 | B5: ='Summary-Stats'!I5 -> 0.0038937182
A7: "Stats" | B7: ='Summary-Stats'!C18 -> ESS-RET | C7: ='Summary-Stats'!D18 -> ED-RET | D7: ='Summary-Stats'!E18 -> SP500-RET
A8: AM = Arithmetic Mean | B8: ='Summary-Stats'!C7 -> 0.013091421 | C8: ='Summary-Stats'!D7 -> 0.0088689366 | D8: ='Summary-Stats'!E7 -> 0.0083072176
A9: GM = Geometric Mean | B9: ='Summary-Stats'!C8 -> 0.011216185 | C9: ='Summary-Stats'!D8 -> 0.0076266734 | D9: ='Summary-Stats'!E8 -> 0.0073394951
A10: Var = Sample Variance | B10: ='Summary-Stats'!C11 -> 0.0037651608 | C10: ='Summary-Stats'!D11 -> 0.0025081504 | D10: ='Summary-Stats'!E11 -> 0.0019159971
A11: Risk = Sample Std. Dev. | B11: ='Summary-Stats'!C12 -> 0.061360906 | C11: ='Summary-Stats'!D12 -> 0.050081438 | D11: ='Summary-Stats'!E12 -> 0.043772104
A13: Var-Cov | B13: =B7 -> ESS-RET | C13: =C7 -> ED-RET
A14: =B13 -> ESS-RET | B14: ='Summary-Stats'!C19 -> 0.0037651608 | C14: ='Summary-Stats'!D19 -> 0.00076141857
A15: =C13 -> ED-RET | B15: ='Summary-Stats'!C20 -> 0.00076141857 | C15: ='Summary-Stats'!D20 -> 0.0025081504
A17: STATS APPROACH: FUTURE MONTHLY RETURNS AND RISK
A18: Oct 1 Portfolio | B18: =B13 -> ESS-RET | C18: =C13 -> ED-RET
A19: r_AM --> E[r] | B19: =B8 -> 0.013091421 | C19: =C8 -> 0.0088689366
A20: s --> Future Risk = "Sigma" | B20: =B11 -> 0.061360906 | C20: =C11 -> 0.050081438
A21: Risk Premium = E[r] - rf | B21: =B19-$B$5 -> 0.0091977033 | C21: =C19-$B$5 -> 0.0049752184
A22: Sharpe Ratio = Risk Premium/Risk = (E[r] - r_f)/sigma | B22: =B21/B20 -> 0.14989517 | C22: =C21/C20 -> 0.099342563
A24: w1 (ESS) | B24: w2 (ED) | C24: Risk(SRA) | D24: E[SRA-RET]
A25: -0.2 | B25: =1-A25 -> 1.2 | C25: =SQRT(($B$20^2)*(A25^2) + ($C$20^2)*(B25^2) + 2*A25*B25*$B$15) -> 0.058282606 | D25: =A25*$B$19+B25*$C$19 -> 0.0080244397
A26: =A25+0.1 -> -0.1 | B26: =1-A26 -> 1.1 | C26: =SQRT(($B$20^2)*(A26^2) + ($C$20^2)*(B26^2) + 2*A26*B26*$B$15) -> 0.053898066 | D26: =A26*$B$19+B26*$C$19 -> 0.0084466882
A27: =A26+0.1 -> 0 | B27: =1-A27 -> 1 | C27: =SQRT(($B$20^2)*(A27^2) + ($C$20^2)*(B27^2) + 2*A27*B27*$B$15) -> 0.050081438 | D27: =A27*$B$19+B27*$C$19 -> 0.0088689366
A28: =A27+0.1 -> 0.1 | B28: =1-A28 -> 0.9 | C28: =SQRT(($B$20^2)*(A28^2) + ($C$20^2)*(B28^2) + 2*A28*B28*$B$15) -> 0.046971362 | D28: =A28*$B$19+B28*$C$19 -> 0.0092911851
A29: =A28+0.1 -> 0.2 | B29: =1-A29 -> 0.8 | C29: =SQRT(($B$20^2)*(A29^2) + ($C$20^2)*(B29^2) + 2*A29*B29*$B$15) -> 0.044715508 | D29: =A29*$B$19+B29*$C$19 -> 0.0097134336
A30: =A29+0.1 -> 0.3 | B30: =1-A30 -> 0.7 | C30: =SQRT(($B$20^2)*(A30^2) + ($C$20^2)*(B30^2) + 2*A30*B30*$B$15) -> 0.04344714 | D30: =A30*$B$19+B30*$C$19 -> 0.010135682
A31: =A30+0.1 -> 0.4 | B31: =1-A31 -> 0.6 | C31: =SQRT(($B$20^2)*(A31^2) + ($C$20^2)*(B31^2) + 2*A31*B31*$B$15) -> 0.043253217 | D31: =A31*$B$19+B31*$C$19 -> 0.010557931
A32: =A31+0.1 -> 0.5 | B32: =1-A32 -> 0.5 | C32: =SQRT(($B$20^2)*(A32^2) + ($C$20^2)*(B32^2) + 2*A32*B32*$B$15) -> 0.0441479 | D32: =A32*$B$19+B32*$C$19 -> 0.010980179
A33: =A32+0.1 -> 0.6 | B33: =1-A33 -> 0.4 | C33: =SQRT(($B$20^2)*(A33^2) + ($C$20^2)*(B33^2) + 2*A33*B33*$B$15) -> 0.046067807 | D33: =A33*$B$19+B33*$C$19 -> 0.011402428
A34: =A33+0.1 -> 0.7 | B34: =1-A34 -> 0.3 | C34: =SQRT(($B$20^2)*(A34^2) + ($C$20^2)*(B34^2) + 2*A34*B34*$B$15) -> 0.048892311 | D34: =A34*$B$19+B34*$C$19 -> 0.011824676
A35: =A34+0.1 -> 0.8 | B35: =1-A35 -> 0.2 | C35: =SQRT(($B$20^2)*(A35^2) + ($C$20^2)*(B35^2) + 2*A35*B35*$B$15) -> 0.052475545 | D35: =A35*$B$19+B35*$C$19 -> 0.012246925
A36: =A35+0.1 -> 0.9 | B36: =1-A36 -> 0.1 | C36: =SQRT(($B$20^2)*(A36^2) + ($C$20^2)*(B36^2) + 2*A36*B36*$B$15) -> 0.056673778 | D36: =A36*$B$19+B36*$C$19 -> 0.012669173
A37: =A36+0.1 -> 1 | B37: =1-A37 -> 0 | C37: =SQRT(($B$20^2)*(A37^2) + ($C$20^2)*(B37^2) + 2*A37*B37*$B$15) -> 0.061360906 | D37: =A37*$B$19+B37*$C$19 -> 0.013091421
... A39: =A38+0.1 -> 1.2 | B39: =1-A39 -> -0.2 | C39: =SQRT(($B$20^2)*(A39^2) + ($C$20^2)*(B39^2) + 2*A39*B39*$B$15) -> 0.071810003 | D39: =A39*$B$19+B39*$C$19 -> 0.013935918
A41: Optimal SRA (Stats Approach)
A42: r1_AM --> E[r_1] | B42: =B19 -> 0.013091421 | D42: Optimal w1 = | F42: =(B44*B47-B45*B48)/(B44*(B47-B48)+B45*(B46-B48)) -> 0.62176326
A43: r2_AM --> E[r_2] | B43: =C19 -> 0.0088689366 | D43: Optimal w2 = | F43: =1-F42 -> 0.37823674
A44: RP_1 = E[r_1] - r_f | B44: =B42-$B$5 -> 0.0091977033 | D44: E[r_SRA] | F44: =F42*B42+F43*B43 -> 0.011494323
A45: RP_2 = E[r_2] - r_f | B45: =B43-$B$5 -> 0.0049752184 | D45: RP_SRA = | F45: =F44-B5 -> 0.0076006043
A46: (s1)^2 --> (Sigma_1 )^2 | B46: =B20^2 -> 0.0037651608 | D46: SRA-RISK = | F46: =SQRT(((F42)^2*B46)+((F43)^2*B47)+(2*F42*F43*B48)) -> 0.046610371
A47: (s2)^2 -> (Sigma_2 )^2 | B47: =C20^2 -> 0.0025081504 | D47: Optimal SRA Sharpe Ratio = | F47: =F45/F46 -> 0.16306681
A48: Cov12 --> sigma_12 | B48: =B15 -> 0.00076141857
...

Sheet SHRINKAGE-PORTFOLIO
A2: Portfolio by Shrinkage Approach
A4: OCTOBER MONTHLY RETURNS ON 90-DAY US T-BILLS
A5: Date | B5: r_free (mo)
A6: ='Summary-Stats'!H5 -> 45566 | B6: ='Summary-Stats'!I5 -> 0.0038937182
B9: "Stats" | C9: ESS-RET | D9: ED-RET | E9: SP500-RET
B10: AM = Arithmetic Mean | C10: 0.013091421 | D10: 0.0088689366 | E10: 0.0083072176
B11: GM = Geometric Mean | C11: 0.011216185 | D11: 0.0076266734 | E11: 0.0073394951
B12: Var = Sample Variance | C12: 0.0037651608 | D12: 0.0025081504 | E12: 0.0019159971
B13: Risk = Sample Std. Dev. | C13: 0.061360906 | D13: 0.050081438 | E13: 0.043772104
B15: Var-Cov | C15: ESS-RET | D15: ED-RET
B16: ESS-RET | C16: 0.0037651608 | D16: 0.00076141857
B17: ED-RET | C17: 0.00076141857 | D17: 0.0025081504
B19: SHRINKAGE APPROACH: FUTURE MONTHLY RETURNS AND RISK
B20: Aug 1 Portfolio | C20: =C15 -> ESS-RET | D20: =D15 -> ED-RET
B21: (r_AM + r_SP500)/2--> E[r] | C21: =(C10+E10)/2 -> 0.01069932 | D21: =(D10+E10)/2 -> 0.0085880771
B22: 1.3(s_r + s_SP500)/2 --> Future Risk = "Sigma" | C22: =1.3*(C13+E13)/2 -> 0.068336456 | D22: =1.3*(D13+E13)/2 -> 0.061004802
B23: Risk Premium = E[r] - rf | C23: =C21-$B$6 -> 0.0068056013 | D23: =D21-$B$6 -> 0.0046943589
B24: Sharpe Ratio = Risk Premium/Risk = (E[r] - r_f)/sigma | C24: =C23/C22 -> 0.099589614 | D24: =D23/D22 -> 0.076950645
B27: w1 (ESS)) | C27: w2 (ED) | D27: Risk(SRA) | E27: E[SRA-RET]
B28: -0.2 | C28: =1-B28 -> 1.2 | D28: =SQRT(($C$22^2)*(B28^2) + ($D$22^2)*(C28^2) + 2*B28*C28*$C$17) -> 0.071974979 | E28: =B28*$C$21+C28*$D$21 -> 0.0081658287
B29: =B28+0.1 -> -0.1 | C29: =1-B29 -> 1.1 | D29: =SQRT(($C$22^2)*(B29^2) + ($D$22^2)*(C29^2) + 2*B29*C29*$C$17) -> 0.066198985 | E29: =B29*$C$21+C29*$D$21 -> 0.0083769529
B30: =B29+0.1 -> 0 | C30: =1-B30 -> 1 | D30: =SQRT(($C$22^2)*(B30^2) + ($D$22^2)*(C30^2) + 2*B30*C30*$C$17) -> 0.061004802 | E30: =B30*$C$21+C30*$D$21 -> 0.0085880771
B31: =B30+0.1 -> 0.1 | C31: =1-B31 -> 0.9 | D31: =SQRT(($C$22^2)*(B31^2) + ($D$22^2)*(C31^2) + 2*B31*C31*$C$17) -> 0.056552972 | E31: =B31*$C$21+C31*$D$21 -> 0.0087992014
B32: =B31+0.1 -> 0.2 | C32: =1-B32 -> 0.8 | D32: =SQRT(($C$22^2)*(B32^2) + ($D$22^2)*(C32^2) + 2*B32*C32*$C$17) -> 0.053030781 | E32: =B32*$C$21+C32*$D$21 -> 0.0090103256
B33: =B32+0.1 -> 0.3 | C33: =1-B33 -> 0.7 | D33: =SQRT(($C$22^2)*(B33^2) + ($D$22^2)*(C33^2) + 2*B33*C33*$C$17) -> 0.050632611 | E33: =B33*$C$21+C33*$D$21 -> 0.0092214499
B34: =B33+0.1 -> 0.4 | C34: =1-B34 -> 0.6 | D34: =SQRT(($C$22^2)*(B34^2) + ($D$22^2)*(C34^2) + 2*B34*C34*$C$17) -> 0.049522028 | E34: =B34*$C$21+C34*$D$21 -> 0.0094325741
B35: =B34+0.1 -> 0.5 | C35: =1-B35 -> 0.5 | D35: =SQRT(($C$22^2)*(B35^2) + ($D$22^2)*(C35^2) + 2*B35*C35*$C$17) -> 0.049785275 | E35: =B35*$C$21+C35*$D$21 -> 0.0096436983
B36: =B35+0.1 -> 0.6 | C36: =1-B36 -> 0.4 | D36: =SQRT(($C$22^2)*(B36^2) + ($D$22^2)*(C36^2) + 2*B36*C36*$C$17) -> 0.051401248 | E36: =B36*$C$21+C36*$D$21 -> 0.0098548226
B37: =B36+0.1 -> 0.7 | C37: =1-B37 -> 0.3 | D37: =SQRT(($C$22^2)*(B37^2) + ($D$22^2)*(C37^2) + 2*B37*C37*$C$17) -> 0.054249198 | E37: =B37*$C$21+C37*$D$21 -> 0.010065947
B38: =B37+0.1 -> 0.8 | C38: =1-B38 -> 0.2 | D38: =SQRT(($C$22^2)*(B38^2) + ($D$22^2)*(C38^2) + 2*B38*C38*$C$17) -> 0.058148388 | E38: =B38*$C$21+C38*$D$21 -> 0.010277071
B39: =B38+0.1 -> 0.9 | C39: =1-B39 -> 0.1 | D39: =SQRT(($C$22^2)*(B39^2) + ($D$22^2)*(C39^2) + 2*B39*C39*$C$17) -> 0.062903632 | E39: =B39*$C$21+C39*$D$21 -> 0.010488195
B40: =B39+0.1 -> 1 | C40: =1-B40 -> 0 | D40: =SQRT(($C$22^2)*(B40^2) + ($D$22^2)*(C40^2) + 2*B40*C40*$C$17) -> 0.068336456 | E40: =B40*$C$21+C40*$D$21 -> 0.01069932
... B42: =B41+0.1 -> 1.2 | C42: =1-B42 -> -0.2 | D42: =SQRT(($C$22^2)*(B42^2) + ($D$22^2)*(C42^2) + 2*B42*C42*$C$17) -> 0.080672158 | E42: =B42*$C$21+C42*$D$21 -> 0.011121568
B45: Optimal SRA (ShrinkageApproach)
B46: ESS = "1", ED = "2"
B47: (r1_AM + r_SP500)/2 --> E[r_1] | C47: =C21 -> 0.01069932 | E47: Optimal w1 = | G47: =(C49*C52-C50*C53)/(C49*(C52-C53)+C50*(C51-C53)) -> 0.56511659
B48: (r2_AM + r_SP500)/2 --> E[r_2] | C48: =D21 -> 0.0085880771 | E48: Optimal w2 = | G48: =1-G47 -> 0.43488341
B49: RP_1 = E[r_1] - r_f | C49: =C47-B6 -> 0.0068056013 | E49: E[r_SRA] | G49: =G47*C47+G48*C48 -> 0.0097811752
B50: RP_2 = E[r_2] - r_f | C50: =C48-B6 -> 0.0046943589 | E50: RP_SRA = | G50: =G49-B6 -> 0.005887457
B51: [1.3(s_1 + s_SP500)/2]^2--> (Sigma_1 )^2 | C51: =C22^2 -> 0.0046698713 | E51: SRA-RISK = | G51: =SQRT((C51*G47^2)+(C52*G48^2)+(2*G47*G48*C53)) -> 0.050689711
...

Sheet WIENER-PORTFOLIO
B2: Portfolio by Wiener Approach
B10: OCTOBER MONTHLY RETURNS ON 90-DAY US T-BILLS
B11: Date | C11: r_free (mo)
B12: ='Summary-Stats'!H5 -> 45566 | C12: ='Summary-Stats'!I5 -> 0.0038937182
B14: "Stats" | C14: ESS-RET | D14: ED-RET | E14: SP500-RET
B15: AM = Arithmetic Mean | C15: 0.013091421 | D15: 0.0088689366 | E15: 0.0083072176
B16: GM = Geometric Mean | C16: 0.011216185 | D16: 0.0076266734 | E16: 0.0073394951
B17: Var = Sample Variance | C17: 0.0037651608 | D17: 0.0025081504 | E17: 0.0019159971
B18: Risk = Sample Std. Dev. | C18: 0.061360906 | D18: 0.050081438 | E18: 0.043772104
B20: Var-Cov | C20: ESS-RET | D20: ED-RET
B21: ESS-RET | C21: 0.0037651608 | D21: 0.00076141857
B22: ED-RET | C22: 0.00076141857 | D22: 0.0025081504
B24: WIENER APPROACH: FUTURE MONTHLY RETURNS AND RISK
B25: Oct 1 Portfolio | C25: =C20 -> ESS-RET | D25: =D20 -> ED-RET
B26: r_GM-> E[r] | C26: =C16 -> 0.011216185 | D26: =D16 -> 0.0076266734
B27: s --> Future Risk = "Sigma" | C27: =C18 -> 0.061360906 | D27: =D18 -> 0.050081438
B28: Risk Premium = E[r] - rf | C28: =C26-$C$12 -> 0.0073224669 | D28: =D26-$C$12 -> 0.0037329552
B29: Sharpe Ratio = Risk Premium/Risk = (E[r] - r_f)/sigma | C29: =C28/C27 -> 0.1193344 | D29: =D28/D27 -> 0.074537699
B38: w1 (ESS)) | C38: w2 (ED) | D38: Risk(SRA) | E38: E[SRA-RET]
B39: -0.2 | C39: =1-B39 -> 1.2 | D39: =SQRT(($C$27^2)*(B39^2) + ($D$27^2)*(C39^2) + 2*B39*C39*$C$22) -> 0.058282606 | E39: =B39*$C$26+C39*$D$26 -> 0.006908771
B40: =B39+0.1 -> -0.1 | C40: =1-B40 -> 1.1 | D40: =SQRT(($C$27^2)*(B40^2) + ($D$27^2)*(C40^2) + 2*B40*C40*$C$22) -> 0.053898066 | E40: =B40*$C$26+C40*$D$26 -> 0.0072677222
B41: =B40+0.1 -> 0 | C41: =1-B41 -> 1 | D41: =SQRT(($C$27^2)*(B41^2) + ($D$27^2)*(C41^2) + 2*B41*C41*$C$22) -> 0.050081438 | E41: =B41*$C$26+C41*$D$26 -> 0.0076266734
B42: =B41+0.1 -> 0.1 | C42: =1-B42 -> 0.9 | D42: =SQRT(($C$27^2)*(B42^2) + ($D$27^2)*(C42^2) + 2*B42*C42*$C$22) -> 0.046971362 | E42: =B42*$C$26+C42*$D$26 -> 0.0079856246
B43: =B42+0.1 -> 0.2 | C43: =1-B43 -> 0.8 | D43: =SQRT(($C$27^2)*(B43^2) + ($D$27^2)*(C43^2) + 2*B43*C43*$C$22) -> 0.044715508 | E43: =B43*$C$26+C43*$D$26 -> 0.0083445757
B44: =B43+0.1 -> 0.3 | C44: =1-B44 -> 0.7 | D44: =SQRT(($C$27^2)*(B44^2) + ($D$27^2)*(C44^2) + 2*B44*C44*$C$22) -> 0.04344714 | E44: =B44*$C$26+C44*$D$26 -> 0.0087035269
B45: =B44+0.1 -> 0.4 | C45: =1-B45 -> 0.6 | D45: =SQRT(($C$27^2)*(B45^2) + ($D$27^2)*(C45^2) + 2*B45*C45*$C$22) -> 0.043253217 | E45: =B45*$C$26+C45*$D$26 -> 0.0090624781
B46: =B45+0.1 -> 0.5 | C46: =1-B46 -> 0.5 | D46: =SQRT(($C$27^2)*(B46^2) + ($D$27^2)*(C46^2) + 2*B46*C46*$C$22) -> 0.0441479 | E46: =B46*$C$26+C46*$D$26 -> 0.0094214293
B47: =B46+0.1 -> 0.6 | C47: =1-B47 -> 0.4 | D47: =SQRT(($C$27^2)*(B47^2) + ($D$27^2)*(C47^2) + 2*B47*C47*$C$22) -> 0.046067807 | E47: =B47*$C$26+C47*$D$26 -> 0.0097803804
B48: =B47+0.1 -> 0.7 | C48: =1-B48 -> 0.3 | D48: =SQRT(($C$27^2)*(B48^2) + ($D$27^2)*(C48^2) + 2*B48*C48*$C$22) -> 0.048892311 | E48: =B48*$C$26+C48*$D$26 -> 0.010139332
B49: =B48+0.1 -> 0.8 | C49: =1-B49 -> 0.2 | D49: =SQRT(($C$27^2)*(B49^2) + ($D$27^2)*(C49^2) + 2*B49*C49*$C$22) -> 0.052475545 | E49: =B49*$C$26+C49*$D$26 -> 0.010498283
B50: =B49+0.1 -> 0.9 | C50: =1-B50 -> 0.1 | D50: =SQRT(($C$27^2)*(B50^2) + ($D$27^2)*(C50^2) + 2*B50*C50*$C$22) -> 0.056673778 | E50: =B50*$C$26+C50*$D$26 -> 0.010857234
B51: =B50+0.1 -> 1 | C51: =1-B51 -> 0 | D51: =SQRT(($C$27^2)*(B51^2) + ($D$27^2)*(C51^2) + 2*B51*C51*$C$22) -> 0.061360906 | E51: =B51*$C$26+C51*$D$26 -> 0.011216185
... B53: =B52+0.1 -> 1.2 | C53: =1-B53 -> -0.2 | D53: =SQRT(($C$27^2)*(B53^2) + ($D$27^2)*(C53^2) + 2*B53*C53*$C$22) -> 0.071810003 | E53: =B53*$C$26+C53*$D$26 -> 0.011934087
B55: Optimal SRA (Wiener Approach)
B56: ESS = "1", ED = "2"
B57: r1_GM--> E[r_1] | C57: =C26 -> 0.011216185 | E57: Optimal w1 = | G57: =(C59*C62-C60*C63)/(C59*(C62-C63)+C60*(C61-C63)) -> 0.646726
B58: r2_GM--> E[r_2] | C58: =D26 -> 0.0076266734 | E58: Optimal w2 = | G58: =1-G57 -> 0.353274
B59: RP_1 = E[r_1] - r_f | C59: =C57-$C$12 -> 0.0073224669 | E59: E[r_SRA] | G59: =G57*C57+G58*C58 -> 0.009948104
B60: RP_2 = E[r_2] - r_f | C60: =C58-C12 -> 0.0037329552 | E60: RP_SRA = | G60: =G59-C12 -> 0.0060543857
B61: (s1)^2--> (Sigma_1 )^2 | C61: =C27^2 -> 0.0037651608 | E61: SRA-RISK = | G61: =SQRT((C61*G57^2)+(C62*G58^2)+(2*G57*G58*C63)) -> 0.047283653
...

Sheet ITO-PORTFOLIO
A2: Portfolio by Ito Approach
B10: OCTOBER MONTHLY RETURNS ON 90-DAY US T-BILLS
B11: Date | C11: r_free (mo)
B12: ='Summary-Stats'!H5 -> 45566 | C12: ='Summary-Stats'!I5 -> 0.0038937182
B14: "Stats" | C14: ESS-RET | D14: ED-RET | E14: SP500-RET
B15: AM = Arithmetic Mean | C15: 0.013091421 | D15: 0.0088689366 | E15: 0.0083072176
B16: GM = Geometric Mean | C16: 0.011216185 | D16: 0.0076266734 | E16: 0.0073394951
B17: Var = Sample Variance | C17: 0.0037651608 | D17: 0.0025081504 | E17: 0.0019159971
B18: Risk = Sample Std. Dev. | C18: 0.061360906 | D18: 0.050081438 | E18: 0.043772104
B20: Var-Cov | C20: ESS-RET | D20: ED-RET
B21: ESS-RET | C21: 0.0037651608 | D21: 0.00076141857
B22: ED-RET | C22: 0.00076141857 | D22: 0.0025081504
B24: ITO APPROACH: FUTURE MONTHLY RETURNS AND RISK
B25: Oct 1 Portfolio | C25: =C20 -> ESS-RET | D25: =D20 -> ED-RET
B26: r_GM - s^2/2 --> E[r] | C26: =C16-(C17/2) -> 0.0093336048 | D26: =D16-(D17/2) -> 0.0063725982
B27: s --> Future Risk = "Sigma" | C27: =C18 -> 0.061360906 | D27: =D18 -> 0.050081438
B28: Risk Premium = E[r] - rf | C28: =C26-$C$12 -> 0.0054398865 | D28: =D26-$C$12 -> 0.0024788799
B29: Sharpe Ratio = Risk Premium/Risk = (E[r] - r_f)/sigma | C29: =C28/C27 -> 0.088653948 | D29: =D28/D27 -> 0.04949698
B37: This graph illustrates the "curved" relationship between r_SRA and risk_SRA
B38: w1 (ESS) | C38: w2 (ED) | D38: Risk(SRA) | E38: E[SRA-RET]
B39: -0.2 | C39: =1-B39 -> 1.2 | D39: =SQRT(($C$27^2)*(B39^2) + ($D$27^2)*(C39^2) + 2*B39*C39*$C$22) -> 0.058282606 | E39: =B39*$C$26+C39*$D$26 -> 0.0057803969
B40: =B39+0.1 -> -0.1 | C40: =1-B40 -> 1.1 | D40: =SQRT(($C$27^2)*(B40^2) + ($D$27^2)*(C40^2) + 2*B40*C40*$C$22) -> 0.053898066 | E40: =B40*$C$26+C40*$D$26 -> 0.0060764975
B41: =B40+0.1 -> 0 | C41: =1-B41 -> 1 | D41: =SQRT(($C$27^2)*(B41^2) + ($D$27^2)*(C41^2) + 2*B41*C41*$C$22) -> 0.050081438 | E41: =B41*$C$26+C41*$D$26 -> 0.0063725982
B42: =B41+0.1 -> 0.1 | C42: =1-B42 -> 0.9 | D42: =SQRT(($C$27^2)*(B42^2) + ($D$27^2)*(C42^2) + 2*B42*C42*$C$22) -> 0.046971362 | E42: =B42*$C$26+C42*$D$26 -> 0.0066686988
B43: =B42+0.1 -> 0.2 | C43: =1-B43 -> 0.8 | D43: =SQRT(($C$27^2)*(B43^2) + ($D$27^2)*(C43^2) + 2*B43*C43*$C$22) -> 0.044715508 | E43: =B43*$C$26+C43*$D$26 -> 0.0069647995
B44: =B43+0.1 -> 0.3 | C44: =1-B44 -> 0.7 | D44: =SQRT(($C$27^2)*(B44^2) + ($D$27^2)*(C44^2) + 2*B44*C44*$C$22) -> 0.04344714 | E44: =B44*$C$26+C44*$D$26 -> 0.0072609001
B45: =B44+0.1 -> 0.4 | C45: =1-B45 -> 0.6 | D45: =SQRT(($C$27^2)*(B45^2) + ($D$27^2)*(C45^2) + 2*B45*C45*$C$22) -> 0.043253217 | E45: =B45*$C$26+C45*$D$26 -> 0.0075570008
B46: =B45+0.1 -> 0.5 | C46: =1-B46 -> 0.5 | D46: =SQRT(($C$27^2)*(B46^2) + ($D$27^2)*(C46^2) + 2*B46*C46*$C$22) -> 0.0441479 | E46: =B46*$C$26+C46*$D$26 -> 0.0078531015
B47: =B46+0.1 -> 0.6 | C47: =1-B47 -> 0.4 | D47: =SQRT(($C$27^2)*(B47^2) + ($D$27^2)*(C47^2) + 2*B47*C47*$C$22) -> 0.046067807 | E47: =B47*$C$26+C47*$D$26 -> 0.0081492021
B48: =B47+0.1 -> 0.7 | C48: =1-B48 -> 0.3 | D48: =SQRT(($C$27^2)*(B48^2) + ($D$27^2)*(C48^2) + 2*B48*C48*$C$22) -> 0.048892311 | E48: =B48*$C$26+C48*$D$26 -> 0.0084453028
B49: =B48+0.1 -> 0.8 | C49: =1-B49 -> 0.2 | D49: =SQRT(($C$27^2)*(B49^2) + ($D$27^2)*(C49^2) + 2*B49*C49*$C$22) -> 0.052475545 | E49: =B49*$C$26+C49*$D$26 -> 0.0087414034
B50: =B49+0.1 -> 0.9 | C50: =1-B50 -> 0.1 | D50: =SQRT(($C$27^2)*(B50^2) + ($D$27^2)*(C50^2) + 2*B50*C50*$C$22) -> 0.056673778 | E50: =B50*$C$26+C50*$D$26 -> 0.0090375041
B51: =B50+0.1 -> 1 | C51: =1-B51 -> 0 | D51: =SQRT(($C$27^2)*(B51^2) + ($D$27^2)*(C51^2) + 2*B51*C51*$C$22) -> 0.061360906 | E51: =B51*$C$26+C51*$D$26 -> 0.0093336048
... B53: =B52+0.1 -> 1.2 | C53: =1-B53 -> -0.2 | D53: =SQRT(($C$27^2)*(B53^2) + ($D$27^2)*(C53^2) + 2*B53*C53*$C$22) -> 0.071810003 | E53: =B53*$C$26+C53*$D$26 -> 0.0099258061
B55: Optimal SRA (Ito Approach)
B56: ESS = "1", ED = "2"
B57: r1_GM - (s1^2)/2 --> E[r_1] | C57: =C26 -> 0.0093336048 | E57: Optimal w1 = | G57: =(C59*C62-C60*C63)/(C59*(C62-C63)+C60*(C61-C63)) -> 0.69368837
B58: r2_GM - (s2^2)/2 --> E[r_2] | C58: =D26 -> 0.0063725982 | E58: Optimal w2 = | G58: =1-G57 -> 0.30631163
B59: RP_1 = E[r_1] - r_f | C59: =C57-$C$12 -> 0.0054398865 | E59: E[r_SRA] | G59: =G57*C57+G58*C58 -> 0.008426614
B60: RP_2 = E[r_2] - r_f | C60: =C58-C12 -> 0.0024788799 | E60: RP_SRA = | G60: =G59-C12 -> 0.0045328958
...

Sheet PORTFOLIO-SUMMARY
B3: ESS is SRA-Asset 1 and ED is SRA-Asset 2
D5: STATS | E5: SHRINKAGE | F5: WIENER | G5: ITO
B6: SRA Optimal w1 = | D6: ='STATS-PORTFOLIO'!F42 -> 0.62176326 | E6: ='SHRINKAGE-PORTFOLIO'!G47 -> 0.56511659 | F6: ='WIENER-PORTFOLIO'!G57 -> 0.646726 | G6: ='ITO-PORTFOLIO'!G57 -> 0.69368837
B7: SRA Optimal w2 = | D7: ='STATS-PORTFOLIO'!F43 -> 0.37823674 | E7: ='SHRINKAGE-PORTFOLIO'!G48 -> 0.43488341 | F7: ='WIENER-PORTFOLIO'!G58 -> 0.353274 | G7: ='ITO-PORTFOLIO'!G58 -> 0.30631163
B8: E[r_SRA] = | D8: ='STATS-PORTFOLIO'!F44 -> 0.011494323 | E8: ='SHRINKAGE-PORTFOLIO'!G49 -> 0.0097811752 | F8: ='WIENER-PORTFOLIO'!G59 -> 0.009948104 | G8: ='ITO-PORTFOLIO'!G59 -> 0.008426614
B9: RP_SRA = | D9: ='STATS-PORTFOLIO'!F45 -> 0.0076006043 | E9: ='SHRINKAGE-PORTFOLIO'!G50 -> 0.005887457 | F9: ='WIENER-PORTFOLIO'!G60 -> 0.0060543857 | G9: ='ITO-PORTFOLIO'!G60 -> 0.0045328958
B10: SRA-RISK = | D10: ='[1]STATS-PORTFOLIO'!G61 -> 0.13963867 | E10: ='SHRINKAGE-PORTFOLIO'!G51 -> 0.050689711 | F10: ='WIENER-PORTFOLIO'!G61 -> 0.047283653 | G10: ='ITO-PORTFOLIO'!G61 -> 0.048690043
B11: Optimal SRA Sharpe Ratio = | D11: ='STATS-PORTFOLIO'!F46 -> 0.046610371 | E11: ='SHRINKAGE-PORTFOLIO'!G52 -> 0.11614698 | F11: ='WIENER-PORTFOLIO'!G62 -> 0.12804395 | G11: ='ITO-PORTFOLIO'!G62 -> 0.093096976
B12: Threshold "boxed c" (for beta = 1) = | D12: ='STATS-PORTFOLIO'!B55 -> 1.7492546 | E12: ='SHRINKAGE-PORTFOLIO'!C62 -> 1.1456663 | F12: ='WIENER-PORTFOLIO'!C71 -> 1.3539981 | G12: ='ITO-PORTFOLIO'!C70 -> 0.95601658
